Traceback (most recent call last):
  File "/Library/Frameworks/Python.framework/Versions/3.10/lib/python3.10/site-packages/jupyter_cache/executors/utils.py", line 58, in single_nb_execution
    executenb(
  File "/Library/Frameworks/Python.framework/Versions/3.10/lib/python3.10/site-packages/nbclient/client.py", line 1265, in execute
    return NotebookClient(nb=nb, resources=resources, km=km, **kwargs).execute()
  File "/Library/Frameworks/Python.framework/Versions/3.10/lib/python3.10/site-packages/jupyter_core/utils/__init__.py", line 166, in wrapped
    return loop.run_until_complete(inner)
  File "/Library/Frameworks/Python.framework/Versions/3.10/lib/python3.10/asyncio/base_events.py", line 646, in run_until_complete
    return future.result()
  File "/Library/Frameworks/Python.framework/Versions/3.10/lib/python3.10/site-packages/nbclient/client.py", line 703, in async_execute
    await self.async_execute_cell(
  File "/Library/Frameworks/Python.framework/Versions/3.10/lib/python3.10/site-packages/nbclient/client.py", line 1021, in async_execute_cell
    await self._check_raise_for_error(cell, cell_index, exec_reply)
  File "/Library/Frameworks/Python.framework/Versions/3.10/lib/python3.10/site-packages/nbclient/client.py", line 915, in _check_raise_for_error
    raise CellExecutionError.from_cell_and_msg(cell, exec_reply_content)
nbclient.exceptions.CellExecutionError: An error occurred while executing the following cell:
------------------


# Count the number of unique 'anlys_time' per 'glac_id'
grouped = polygons3.groupby('glac_id')['anlys_time'].nunique()

# Subset rows where 'glac_id' has more than one unique 'anlys_time'
multitemp = polygons3[polygons3['glac_id'].isin(grouped[grouped > 1].index)]

# Check if subset was successful
multitemp.shape, polygons3.shape
------------------

[0;31m---------------------------------------------------------------------------[0m
[0;31mNameError[0m                                 Traceback (most recent call last)
Cell [0;32mIn [12], line 2[0m
[1;32m      1[0m [38;5;66;03m# Count the number of unique 'anlys_time' per 'glac_id'[39;00m
[0;32m----> 2[0m grouped [38;5;241m=[39m [43mpolygons3[49m[38;5;241m.[39mgroupby([38;5;124m'[39m[38;5;124mglac_id[39m[38;5;124m'[39m)[[38;5;124m'[39m[38;5;124manlys_time[39m[38;5;124m'[39m][38;5;241m.[39mnunique()
[1;32m      4[0m [38;5;66;03m# Subset rows where 'glac_id' has more than one unique 'anlys_time'[39;00m
[1;32m      5[0m multitemp [38;5;241m=[39m polygons3[polygons3[[38;5;124m'[39m[38;5;124mglac_id[39m[38;5;124m'[39m][38;5;241m.[39misin(grouped[grouped [38;5;241m>[39m [38;5;241m1[39m][38;5;241m.[39mindex)]

[0;31mNameError[0m: name 'polygons3' is not defined
NameError: name 'polygons3' is not defined

