Traceback (most recent call last):
  File "/Library/Frameworks/Python.framework/Versions/3.10/lib/python3.10/site-packages/jupyter_cache/executors/utils.py", line 58, in single_nb_execution
    executenb(
  File "/Library/Frameworks/Python.framework/Versions/3.10/lib/python3.10/site-packages/nbclient/client.py", line 1265, in execute
    return NotebookClient(nb=nb, resources=resources, km=km, **kwargs).execute()
  File "/Library/Frameworks/Python.framework/Versions/3.10/lib/python3.10/site-packages/jupyter_core/utils/__init__.py", line 166, in wrapped
    return loop.run_until_complete(inner)
  File "/Library/Frameworks/Python.framework/Versions/3.10/lib/python3.10/asyncio/base_events.py", line 646, in run_until_complete
    return future.result()
  File "/Library/Frameworks/Python.framework/Versions/3.10/lib/python3.10/site-packages/nbclient/client.py", line 703, in async_execute
    await self.async_execute_cell(
  File "/Library/Frameworks/Python.framework/Versions/3.10/lib/python3.10/site-packages/nbclient/client.py", line 1021, in async_execute_cell
    await self._check_raise_for_error(cell, cell_index, exec_reply)
  File "/Library/Frameworks/Python.framework/Versions/3.10/lib/python3.10/site-packages/nbclient/client.py", line 915, in _check_raise_for_error
    raise CellExecutionError.from_cell_and_msg(cell, exec_reply_content)
nbclient.exceptions.CellExecutionError: An error occurred while executing the following cell:
------------------
# Load Esri shapefiles as geopandas dataframes
points = gpd.read_file("GLIMS_20230716/glims_download_13173/glims_points.shp")
polygons = gpd.read_file("GLIMS_20230716/glims_download_13173/glims_polygons.shp")
#polygons2 = gpd.read_file("GLIMS_20230716/polygons2.csv")
------------------

[0;31m---------------------------------------------------------------------------[0m
[0;31mCPLE_OpenFailedError[0m                      Traceback (most recent call last)
File [0;32mfiona/_shim.pyx:83[0m, in [0;36mfiona._shim.gdal_open_vector[0;34m()[0m

File [0;32mfiona/_err.pyx:291[0m, in [0;36mfiona._err.exc_wrap_pointer[0;34m()[0m

[0;31mCPLE_OpenFailedError[0m: GLIMS_20230716/glims_download_13173/glims_points.shp: No such file or directory

During handling of the above exception, another exception occurred:

[0;31mDriverError[0m                               Traceback (most recent call last)
Cell [0;32mIn [2], line 2[0m
[1;32m      1[0m [38;5;66;03m# Load Esri shapefiles as geopandas dataframes[39;00m
[0;32m----> 2[0m points [38;5;241m=[39m [43mgpd[49m[38;5;241;43m.[39;49m[43mread_file[49m[43m([49m[38;5;124;43m"[39;49m[38;5;124;43mGLIMS_20230716/glims_download_13173/glims_points.shp[39;49m[38;5;124;43m"[39;49m[43m)[49m
[1;32m      3[0m polygons [38;5;241m=[39m gpd[38;5;241m.[39mread_file([38;5;124m"[39m[38;5;124mGLIMS_20230716/glims_download_13173/glims_polygons.shp[39m[38;5;124m"[39m)

File [0;32m/Library/Frameworks/Python.framework/Versions/3.10/lib/python3.10/site-packages/geopandas/io/file.py:253[0m, in [0;36m_read_file[0;34m(filename, bbox, mask, rows, engine, **kwargs)[0m
[1;32m    250[0m     path_or_bytes [38;5;241m=[39m filename
[1;32m    252[0m [38;5;28;01mif[39;00m engine [38;5;241m==[39m [38;5;124m"[39m[38;5;124mfiona[39m[38;5;124m"[39m:
[0;32m--> 253[0m     [38;5;28;01mreturn[39;00m [43m_read_file_fiona[49m[43m([49m
[1;32m    254[0m [43m        [49m[43mpath_or_bytes[49m[43m,[49m[43m [49m[43mfrom_bytes[49m[43m,[49m[43m [49m[43mbbox[49m[38;5;241;43m=[39;49m[43mbbox[49m[43m,[49m[43m [49m[43mmask[49m[38;5;241;43m=[39;49m[43mmask[49m[43m,[49m[43m [49m[43mrows[49m[38;5;241;43m=[39;49m[43mrows[49m[43m,[49m[43m [49m[38;5;241;43m*[39;49m[38;5;241;43m*[39;49m[43mkwargs[49m
[1;32m    255[0m [43m    [49m[43m)[49m
[1;32m    256[0m [38;5;28;01melif[39;00m engine [38;5;241m==[39m [38;5;124m"[39m[38;5;124mpyogrio[39m[38;5;124m"[39m:
[1;32m    257[0m     [38;5;28;01mreturn[39;00m _read_file_pyogrio(
[1;32m    258[0m         path_or_bytes, bbox[38;5;241m=[39mbbox, mask[38;5;241m=[39mmask, rows[38;5;241m=[39mrows, [38;5;241m*[39m[38;5;241m*[39mkwargs
[1;32m    259[0m     )

File [0;32m/Library/Frameworks/Python.framework/Versions/3.10/lib/python3.10/site-packages/geopandas/io/file.py:294[0m, in [0;36m_read_file_fiona[0;34m(path_or_bytes, from_bytes, bbox, mask, rows, **kwargs)[0m
[1;32m    291[0m     reader [38;5;241m=[39m fiona[38;5;241m.[39mopen
[1;32m    293[0m [38;5;28;01mwith[39;00m fiona_env():
[0;32m--> 294[0m     [38;5;28;01mwith[39;00m [43mreader[49m[43m([49m[43mpath_or_bytes[49m[43m,[49m[43m [49m[38;5;241;43m*[39;49m[38;5;241;43m*[39;49m[43mkwargs[49m[43m)[49m [38;5;28;01mas[39;00m features:
[1;32m    295[0m 
[1;32m    296[0m         [38;5;66;03m# In a future Fiona release the crs attribute of features will[39;00m
[1;32m    297[0m         [38;5;66;03m# no longer be a dict, but will behave like a dict. So this should[39;00m
[1;32m    298[0m         [38;5;66;03m# be forwards compatible[39;00m
[1;32m    299[0m         crs [38;5;241m=[39m (
[1;32m    300[0m             features[38;5;241m.[39mcrs[[38;5;124m"[39m[38;5;124minit[39m[38;5;124m"[39m]
[1;32m    301[0m             [38;5;28;01mif[39;00m features[38;5;241m.[39mcrs [38;5;129;01mand[39;00m [38;5;124m"[39m[38;5;124minit[39m[38;5;124m"[39m [38;5;129;01min[39;00m features[38;5;241m.[39mcrs
[1;32m    302[0m             [38;5;28;01melse[39;00m features[38;5;241m.[39mcrs_wkt
[1;32m    303[0m         )
[1;32m    305[0m         [38;5;66;03m# handle loading the bounding box[39;00m

File [0;32m/Library/Frameworks/Python.framework/Versions/3.10/lib/python3.10/site-packages/fiona/env.py:408[0m, in [0;36mensure_env_with_credentials.<locals>.wrapper[0;34m(*args, **kwargs)[0m
[1;32m    405[0m [38;5;129m@wraps[39m(f)
[1;32m    406[0m [38;5;28;01mdef[39;00m [38;5;21mwrapper[39m([38;5;241m*[39margs, [38;5;241m*[39m[38;5;241m*[39mkwargs):
[1;32m    407[0m     [38;5;28;01mif[39;00m local[38;5;241m.[39m_env:
[0;32m--> 408[0m         [38;5;28;01mreturn[39;00m [43mf[49m[43m([49m[38;5;241;43m*[39;49m[43margs[49m[43m,[49m[43m [49m[38;5;241;43m*[39;49m[38;5;241;43m*[39;49m[43mkwargs[49m[43m)[49m
[1;32m    409[0m     [38;5;28;01melse[39;00m:
[1;32m    410[0m         [38;5;28;01mif[39;00m [38;5;28misinstance[39m(args[[38;5;241m0[39m], [38;5;28mstr[39m):

File [0;32m/Library/Frameworks/Python.framework/Versions/3.10/lib/python3.10/site-packages/fiona/__init__.py:264[0m, in [0;36mopen[0;34m(fp, mode, driver, schema, crs, encoding, layer, vfs, enabled_drivers, crs_wkt, **kwargs)[0m
[1;32m    261[0m     path [38;5;241m=[39m parse_path(fp)
[1;32m    263[0m [38;5;28;01mif[39;00m mode [38;5;129;01min[39;00m ([38;5;124m'[39m[38;5;124ma[39m[38;5;124m'[39m, [38;5;124m'[39m[38;5;124mr[39m[38;5;124m'[39m):
[0;32m--> 264[0m     c [38;5;241m=[39m [43mCollection[49m[43m([49m[43mpath[49m[43m,[49m[43m [49m[43mmode[49m[43m,[49m[43m [49m[43mdriver[49m[38;5;241;43m=[39;49m[43mdriver[49m[43m,[49m[43m [49m[43mencoding[49m[38;5;241;43m=[39;49m[43mencoding[49m[43m,[49m
[1;32m    265[0m [43m                   [49m[43mlayer[49m[38;5;241;43m=[39;49m[43mlayer[49m[43m,[49m[43m [49m[43menabled_drivers[49m[38;5;241;43m=[39;49m[43menabled_drivers[49m[43m,[49m[43m [49m[38;5;241;43m*[39;49m[38;5;241;43m*[39;49m[43mkwargs[49m[43m)[49m
[1;32m    266[0m [38;5;28;01melif[39;00m mode [38;5;241m==[39m [38;5;124m'[39m[38;5;124mw[39m[38;5;124m'[39m:
[1;32m    267[0m     [38;5;28;01mif[39;00m schema:
[1;32m    268[0m         [38;5;66;03m# Make an ordered dict of schema properties.[39;00m

File [0;32m/Library/Frameworks/Python.framework/Versions/3.10/lib/python3.10/site-packages/fiona/collection.py:162[0m, in [0;36mCollection.__init__[0;34m(self, path, mode, driver, schema, crs, encoding, layer, vsi, archive, enabled_drivers, crs_wkt, ignore_fields, ignore_geometry, **kwargs)[0m
[1;32m    160[0m [38;5;28;01mif[39;00m [38;5;28mself[39m[38;5;241m.[39mmode [38;5;241m==[39m [38;5;124m'[39m[38;5;124mr[39m[38;5;124m'[39m:
[1;32m    161[0m     [38;5;28mself[39m[38;5;241m.[39msession [38;5;241m=[39m Session()
[0;32m--> 162[0m     [38;5;28;43mself[39;49m[38;5;241;43m.[39;49m[43msession[49m[38;5;241;43m.[39;49m[43mstart[49m[43m([49m[38;5;28;43mself[39;49m[43m,[49m[43m [49m[38;5;241;43m*[39;49m[38;5;241;43m*[39;49m[43mkwargs[49m[43m)[49m
[1;32m    163[0m [38;5;28;01melif[39;00m [38;5;28mself[39m[38;5;241m.[39mmode [38;5;129;01min[39;00m ([38;5;124m'[39m[38;5;124ma[39m[38;5;124m'[39m, [38;5;124m'[39m[38;5;124mw[39m[38;5;124m'[39m):
[1;32m    164[0m     [38;5;28mself[39m[38;5;241m.[39msession [38;5;241m=[39m WritingSession()

File [0;32mfiona/ogrext.pyx:540[0m, in [0;36mfiona.ogrext.Session.start[0;34m()[0m

File [0;32mfiona/_shim.pyx:90[0m, in [0;36mfiona._shim.gdal_open_vector[0;34m()[0m

[0;31mDriverError[0m: GLIMS_20230716/glims_download_13173/glims_points.shp: No such file or directory
DriverError: GLIMS_20230716/glims_download_13173/glims_points.shp: No such file or directory

