Traceback (most recent call last):
  File "/Library/Frameworks/Python.framework/Versions/3.10/lib/python3.10/site-packages/jupyter_cache/executors/utils.py", line 58, in single_nb_execution
    executenb(
  File "/Library/Frameworks/Python.framework/Versions/3.10/lib/python3.10/site-packages/nbclient/client.py", line 1265, in execute
    return NotebookClient(nb=nb, resources=resources, km=km, **kwargs).execute()
  File "/Library/Frameworks/Python.framework/Versions/3.10/lib/python3.10/site-packages/jupyter_core/utils/__init__.py", line 166, in wrapped
    return loop.run_until_complete(inner)
  File "/Library/Frameworks/Python.framework/Versions/3.10/lib/python3.10/asyncio/base_events.py", line 646, in run_until_complete
    return future.result()
  File "/Library/Frameworks/Python.framework/Versions/3.10/lib/python3.10/site-packages/nbclient/client.py", line 703, in async_execute
    await self.async_execute_cell(
  File "/Library/Frameworks/Python.framework/Versions/3.10/lib/python3.10/site-packages/nbclient/client.py", line 1021, in async_execute_cell
    await self._check_raise_for_error(cell, cell_index, exec_reply)
  File "/Library/Frameworks/Python.framework/Versions/3.10/lib/python3.10/site-packages/nbclient/client.py", line 915, in _check_raise_for_error
    raise CellExecutionError.from_cell_and_msg(cell, exec_reply_content)
nbclient.exceptions.CellExecutionError: An error occurred while executing the following cell:
------------------
# Perhaps number of gone glaciers consistent with number of zero area glaciers (db_area)
# Are the "zero area" glaciers also "gone"?
dimensions.eq(0).sum()
------------------

[0;31m---------------------------------------------------------------------------[0m
[0;31mNameError[0m                                 Traceback (most recent call last)
Cell [0;32mIn [18], line 3[0m
[1;32m      1[0m [38;5;66;03m# Perhaps number of gone glaciers consistent with number of zero area glaciers (db_area)[39;00m
[1;32m      2[0m [38;5;66;03m# Are the "zero area" glaciers also "gone"?[39;00m
[0;32m----> 3[0m [43mdimensions[49m[38;5;241m.[39meq([38;5;241m0[39m)[38;5;241m.[39msum()

[0;31mNameError[0m: name 'dimensions' is not defined
NameError: name 'dimensions' is not defined

